<?xml version="1.0" encoding="utf-8"?>
<!-- This URDF was automatically created by SolidWorks to URDF Exporter! Originally created by Stephen Brawner (brawner@gmail.com) 
     Commit Version: 1.6.0-1-g15f4949  Build Version: 1.6.7594.29634
     For more information, please see http://wiki.ros.org/sw_urdf_exporter -->
<robot
  name="myarm_description">
  <link
    name="base_link">
    <inertial>
      <origin
        xyz="-6.9021E-09 -0.027444 -0.0032058"
        rpy="0 0 0" />
      <mass
        value="1.0041" />
      <inertia
        ixx="0.0046558"
        ixy="1.2408E-10"
        ixz="4.7789E-10"
        iyy="0.0091456"
        iyz="7.7707E-06"
        izz="0.0049085" />
    </inertial>
    <visual>
      <origin
        xyz="0 0 0"
        rpy="0 0 0" />
      <geometry>
        <mesh
          filename="package://myarm_description/meshes/base_link.STL" />
      </geometry>
      <material
        name="">
        <color
          rgba="1 1 1 1" />
      </material>
    </visual>
    <collision>
      <origin
        xyz="0 0 0"
        rpy="0 0 0" />
      <geometry>
        <mesh
          filename="package://myarm_description/meshes/base_link.STL" />
      </geometry>
    </collision>
  </link>
  
  <link name="world"/>
	<joint name="fixed" type="fixed">
	         <origin xyz="0 0 0.08" rpy="0 0 0" />
 		 <parent link="world"/>
		 <child link="base_link"/>
	</joint>
  
  <link
    name="link1">
    <inertial>
      <origin
        xyz="0.0059723 0.056817 -3.2105E-06"
        rpy="0 0 0" />
      <mass
        value="0.41965" />
      <inertia
        ixx="0.0012467"
        ixy="4.2158E-05"
        ixz="-6.4547E-08"
        iyy="0.001319"
        iyz="-3.9043E-08"
        izz="0.0012849" />
    </inertial>
    <visual>
      <origin
        xyz="0 0 0"
        rpy="0 0 0" />
      <geometry>
        <mesh
          filename="package://myarm_description/meshes/link1.STL" />
      </geometry>
      <material
        name="">
        <color
          rgba="0.79216 0.81961 0.93333 1" />
      </material>
    </visual>
    <collision>
      <origin
        xyz="0 0 0"
        rpy="0 0 0" />
      <geometry>
        <mesh
          filename="package://myarm_description/meshes/link1.STL" />
      </geometry>
    </collision>
  </link>
  <joint
    name="joint1"
    type="revolute">
    <origin
      xyz="0.01 0 0"
      rpy="1.5708 0 -3.1416" />
    <parent
      link="base_link" />
    <child
      link="link1" />
    <axis
      xyz="0 1 0" />
    <limit
      lower="-3.14"
      upper="3.14"
      effort="50"
      velocity="6.28" />
  </joint>
  <link
    name="link2">
    <inertial>
      <origin
        xyz="0.01568 0.090701 5.7164E-06"
        rpy="0 0 0" />
      <mass
        value="0.47369" />
      <inertia
        ixx="0.0026032"
        ixy="-6.1772E-05"
        ixz="-1.3902E-07"
        iyy="0.00079737"
        iyz="-2.794E-08"
        izz="0.0026857" />
    </inertial>
    <visual>
      <origin
        xyz="0 0 0"
        rpy="0 0 0" />
      <geometry>
        <mesh
          filename="package://myarm_description/meshes/link2.STL" />
      </geometry>
      <material
        name="">
        <color
          rgba="0.79216 0.81961 0.93333 1" />
      </material>
    </visual>
    <collision>
      <origin
        xyz="0 0 0"
        rpy="0 0 0" />
      <geometry>
        <mesh
          filename="package://myarm_description/meshes/link2.STL" />
      </geometry>
    </collision>
  </link>
  <joint
    name="joint2"
    type="revolute">
    <origin
      xyz="0 0.128 0"
      rpy="0.21946 0 0" />
    <parent
      link="link1" />
    <child
      link="link2" />
    <axis
      xyz="-1 0 0" />
    <limit
      lower="-3.14"
      upper="3.14"
      effort="50"
      velocity="6.28" />
  </joint>
  <link
    name="link3">
    <inertial>
      <origin
        xyz="-0.009795 0.085155 -0.0045558"
        rpy="0 0 0" />
      <mass
        value="0.38106" />
      <inertia
        ixx="0.0018705"
        ixy="-7.6065E-06"
        ixz="-3.5665E-07"
        iyy="0.00046644"
        iyz="2.1437E-05"
        izz="0.0018538" />
    </inertial>
    <visual>
      <origin
        xyz="0 0 0"
        rpy="0 0 0" />
      <geometry>
        <mesh
          filename="package://myarm_description/meshes/link3.STL" />
      </geometry>
      <material
        name="">
        <color
          rgba="0.79216 0.81961 0.93333 1" />
      </material>
    </visual>
    <collision>
      <origin
        xyz="0 0 0"
        rpy="0 0 0" />
      <geometry>
        <mesh
          filename="package://myarm_description/meshes/link3.STL" />
      </geometry>
    </collision>
  </link>
  <joint
    name="joint3"
    type="revolute">
    <origin
      xyz="0 0.19 0"
      rpy="1.6545 0 -3.1416" />
    <parent
      link="link2" />
    <child
      link="link3" />
    <axis
      xyz="1 0 0" />
    <limit
      lower="-3.14"
      upper="3.14"
      effort="50"
      velocity="6.28" />
  </joint>
  <link
    name="link4">
    <inertial>
      <origin
        xyz="-0.0095 -0.098926 1.0164E-05"
        rpy="0 0 0" />
      <mass
        value="0.46608" />
      <inertia
        ixx="0.00083153"
        ixy="2.4341E-10"
        ixz="-2.2888E-09"
        iyy="0.00046499"
        iyz="1.1085E-07"
        izz="0.00093012" />
    </inertial>
    <visual>
      <origin
        xyz="0 0 0"
        rpy="0 0 0" />
      <geometry>
        <mesh
          filename="package://myarm_description/meshes/link4.STL" />
      </geometry>
      <material
        name="">
        <color
          rgba="0.79216 0.81961 0.93333 1" />
      </material>
    </visual>
    <collision>
      <origin
        xyz="0 0 0"
        rpy="0 0 0" />
      <geometry>
        <mesh
          filename="package://myarm_description/meshes/link4.STL" />
      </geometry>
    </collision>
  </link>
  <joint
    name="joint4"
    type="revolute">
    <origin
      xyz="0 0.18 0"
      rpy="2.4746 0 0" />
    <parent
      link="link3" />
    <child
      link="link4" />
    <axis
      xyz="1 0 0" />
    <limit
      lower="-3.14"
      upper="3.14"
      effort="50"
      velocity="6.28" />
  </joint>
  
  <transmission name="trans_joint1">
        <type>transmission_interface/SimpleTransmission</type>
        <joint name="joint1">
            <hardwareInterface>hardware_interface/PositionJointInterface</hardwareInterface>
        </joint>
        <actuator name="joint1_motor">
            <hardwareInterface>hardware_interface/PositionJointInterface</hardwareInterface>
            <mechanicalReduction>1</mechanicalReduction>
        </actuator>
    </transmission>
    <transmission name="trans_joint2">
        <type>transmission_interface/SimpleTransmission</type>
        <joint name="joint2">
            <hardwareInterface>hardware_interface/PositionJointInterface</hardwareInterface>
        </joint>
        <actuator name="joint2_motor">
            <hardwareInterface>hardware_interface/PositionJointInterface</hardwareInterface>
            <mechanicalReduction>1</mechanicalReduction>
        </actuator>
    </transmission>
    <transmission name="trans_joint3">
        <type>transmission_interface/SimpleTransmission</type>
        <joint name="joint3">
            <hardwareInterface>hardware_interface/PositionJointInterface</hardwareInterface>
        </joint>
        <actuator name="joint3_motor">
            <hardwareInterface>hardware_interface/PositionJointInterface</hardwareInterface>
            <mechanicalReduction>1</mechanicalReduction>
        </actuator>
    </transmission>
    <transmission name="trans_joint4">
        <type>transmission_interface/SimpleTransmission</type>
        <joint name="joint4">
            <hardwareInterface>hardware_interface/PositionJointInterface</hardwareInterface>
        </joint>
        <actuator name="joint4_motor">
            <hardwareInterface>hardware_interface/PositionJointInterface</hardwareInterface>
            <mechanicalReduction>1</mechanicalReduction>
        </actuator>
    </transmission>
    <gazebo>
        <plugin name="gazebo_ros_control" filename="libgazebo_ros_control.so">
            <robotNamespace>/</robotNamespace>
        </plugin>
    </gazebo>
</robot>
